#start recording
echo 'reset' > /dev/ttyACM0; ./datalogger.py --device /dev/ttyACM0
sudo echo 'sudo warmup'; sudo nohup ./datalogger.py --device /dev/ttyACM0 &
#check process is running
ps aux | grep datalogger.py
#kill process
##sudo kill 1234

#plot
./plot_log.Rsh 2014/11/PID_2014_11_14.txt; evince Rplots.pdf &

exit

#backup
rsync -var ~/data.Xsensor 134.206.175.222:~/www/
##or
rsync -var /home/temp/data.Xsensor 134.206.175.222:~/www/

#test

head -n 128 2014_10_01.txt > test.txt 

./datalogger.py --device test.raw

error:

PID;2014/11/14 11:43:10;7074;7

Traceback (most recent call last):
  File "./datalogger.py", line 110, in <module>
    line+=";"+value[2]
IndexError: list index out of range
